Internal Server Error: /refs/
Traceback (most recent call last):
  File "C:\Users\Arthur\coopvote\venv\lib\site-packages\django\db\backends\utils.py", line 84, in _execute
    return self.cursor.execute(sql, params)
  File "C:\Users\Arthur\coopvote\venv\lib\site-packages\django\db\backends\sqlite3\base.py", line 423, in execute
    return Database.Cursor.execute(self, query, params)
sqlite3.OperationalError: no such table: newref_ref

The above exception was the direct cause of the following exception:

Traceback (most recent call last):
  File "C:\Users\Arthur\coopvote\venv\lib\site-packages\django\core\handlers\exception.py", line 47, in inner
    response = get_response(request)
  File "C:\Users\Arthur\coopvote\venv\lib\site-packages\django\core\handlers\base.py", line 181, in _get_response
    response = wrapped_callback(request, *callback_args, **callback_kwargs)
  File "C:\Users\Arthur\coopvote\newref\views.py", line 57, in refs
    return render(request, template, context)
  File "C:\Users\Arthur\coopvote\venv\lib\site-packages\django\shortcuts.py", line 19, in render
    content = loader.render_to_string(template_name, context, request, using=using)
  File "C:\Users\Arthur\coopvote\venv\lib\site-packages\django\template\loader.py", line 62, in render_to_string
    return template.render(context, request)
  File "C:\Users\Arthur\coopvote\venv\lib\site-packages\django\template\backends\django.py", line 61, in render
    return self.template.render(context)
  File "C:\Users\Arthur\coopvote\venv\lib\site-packages\django\template\base.py", line 170, in render
    return self._render(context)
  File "C:\Users\Arthur\coopvote\venv\lib\site-packages\django\template\base.py", line 162, in _render
    return self.nodelist.render(context)
  File "C:\Users\Arthur\coopvote\venv\lib\site-packages\django\template\base.py", line 938, in render
    bit = node.render_annotated(context)
  File "C:\Users\Arthur\coopvote\venv\lib\site-packages\django\template\base.py", line 905, in render_annotated
    return self.render(context)
  File "C:\Users\Arthur\coopvote\venv\lib\site-packages\django\template\loader_tags.py", line 150, in render
    return compiled_parent._render(context)
  File "C:\Users\Arthur\coopvote\venv\lib\site-packages\django\template\base.py", line 162, in _render
    return self.nodelist.render(context)
  File "C:\Users\Arthur\coopvote\venv\lib\site-packages\django\template\base.py", line 938, in render
    bit = node.render_annotated(context)
  File "C:\Users\Arthur\coopvote\venv\lib\site-packages\django\template\base.py", line 905, in render_annotated
    return self.render(context)
  File "C:\Users\Arthur\coopvote\venv\lib\site-packages\django\templatetags\i18n.py", line 194, in render
    output = self.nodelist.render(context)
  File "C:\Users\Arthur\coopvote\venv\lib\site-packages\django\template\base.py", line 938, in render
    bit = node.render_annotated(context)
  File "C:\Users\Arthur\coopvote\venv\lib\site-packages\django\template\base.py", line 905, in render_annotated
    return self.render(context)
  File "C:\Users\Arthur\coopvote\venv\lib\site-packages\django\template\loader_tags.py", line 62, in render
    result = block.nodelist.render(context)
  File "C:\Users\Arthur\coopvote\venv\lib\site-packages\django\template\base.py", line 938, in render
    bit = node.render_annotated(context)
  File "C:\Users\Arthur\coopvote\venv\lib\site-packages\django\template\base.py", line 905, in render_annotated
    return self.render(context)
  File "C:\Users\Arthur\coopvote\venv\lib\site-packages\django\template\defaulttags.py", line 168, in render
    len_values = len(values)
  File "C:\Users\Arthur\coopvote\venv\lib\site-packages\django\db\models\query.py", line 262, in __len__
    self._fetch_all()
  File "C:\Users\Arthur\coopvote\venv\lib\site-packages\django\db\models\query.py", line 1324, in _fetch_all
    self._result_cache = list(self._iterable_class(self))
  File "C:\Users\Arthur\coopvote\venv\lib\site-packages\django\db\models\query.py", line 51, in __iter__
    results = compiler.execute_sql(chunked_fetch=self.chunked_fetch, chunk_size=self.chunk_size)
  File "C:\Users\Arthur\coopvote\venv\lib\site-packages\django\db\models\sql\compiler.py", line 1169, in execute_sql
    cursor.execute(sql, params)
  File "C:\Users\Arthur\coopvote\venv\lib\site-packages\django\db\backends\utils.py", line 98, in execute
    return super().execute(sql, params)
  File "C:\Users\Arthur\coopvote\venv\lib\site-packages\django\db\backends\utils.py", line 66, in execute
    return self._execute_with_wrappers(sql, params, many=False, executor=self._execute)
  File "C:\Users\Arthur\coopvote\venv\lib\site-packages\django\db\backends\utils.py", line 75, in _execute_with_wrappers
    return executor(sql, params, many, context)
  File "C:\Users\Arthur\coopvote\venv\lib\site-packages\django\db\backends\utils.py", line 84, in _execute
    return self.cursor.execute(sql, params)
  File "C:\Users\Arthur\coopvote\venv\lib\site-packages\django\db\utils.py", line 90, in __exit__
    raise dj_exc_value.with_traceback(traceback) from exc_value
  File "C:\Users\Arthur\coopvote\venv\lib\site-packages\django\db\backends\utils.py", line 84, in _execute
    return self.cursor.execute(sql, params)
  File "C:\Users\Arthur\coopvote\venv\lib\site-packages\django\db\backends\sqlite3\base.py", line 423, in execute
    return Database.Cursor.execute(self, query, params)
django.db.utils.OperationalError: no such table: newref_ref
"GET /refs/ HTTP/1.1" 500 225203
Internal Server Error: /voteadmin_depouillement/622a744b11c44ae44693bd5cd67dc3f3679442b6472f71a320da90c4
Traceback (most recent call last):
  File "C:\Users\Arthur\coopvote\venv\lib\site-packages\django\core\handlers\exception.py", line 47, in inner
    response = get_response(request)
  File "C:\Users\Arthur\coopvote\venv\lib\site-packages\django\core\handlers\base.py", line 181, in _get_response
    response = wrapped_callback(request, *callback_args, **callback_kwargs)
  File "C:\Users\Arthur\coopvote\newref\views.py", line 270, in voteadmin_depouillement
    return render(request, template, context)
  File "C:\Users\Arthur\coopvote\venv\lib\site-packages\django\shortcuts.py", line 19, in render
    content = loader.render_to_string(template_name, context, request, using=using)
  File "C:\Users\Arthur\coopvote\venv\lib\site-packages\django\template\loader.py", line 62, in render_to_string
    return template.render(context, request)
  File "C:\Users\Arthur\coopvote\venv\lib\site-packages\django\template\backends\django.py", line 61, in render
    return self.template.render(context)
  File "C:\Users\Arthur\coopvote\venv\lib\site-packages\django\template\base.py", line 170, in render
    return self._render(context)
  File "C:\Users\Arthur\coopvote\venv\lib\site-packages\django\template\base.py", line 162, in _render
    return self.nodelist.render(context)
  File "C:\Users\Arthur\coopvote\venv\lib\site-packages\django\template\base.py", line 938, in render
    bit = node.render_annotated(context)
  File "C:\Users\Arthur\coopvote\venv\lib\site-packages\django\template\base.py", line 905, in render_annotated
    return self.render(context)
  File "C:\Users\Arthur\coopvote\venv\lib\site-packages\django\template\loader_tags.py", line 150, in render
    return compiled_parent._render(context)
  File "C:\Users\Arthur\coopvote\venv\lib\site-packages\django\template\base.py", line 162, in _render
    return self.nodelist.render(context)
  File "C:\Users\Arthur\coopvote\venv\lib\site-packages\django\template\base.py", line 938, in render
    bit = node.render_annotated(context)
  File "C:\Users\Arthur\coopvote\venv\lib\site-packages\django\template\base.py", line 905, in render_annotated
    return self.render(context)
  File "C:\Users\Arthur\coopvote\venv\lib\site-packages\django\templatetags\i18n.py", line 194, in render
    output = self.nodelist.render(context)
  File "C:\Users\Arthur\coopvote\venv\lib\site-packages\django\template\base.py", line 938, in render
    bit = node.render_annotated(context)
  File "C:\Users\Arthur\coopvote\venv\lib\site-packages\django\template\base.py", line 905, in render_annotated
    return self.render(context)
  File "C:\Users\Arthur\coopvote\venv\lib\site-packages\django\template\loader_tags.py", line 62, in render
    result = block.nodelist.render(context)
  File "C:\Users\Arthur\coopvote\venv\lib\site-packages\django\template\base.py", line 938, in render
    bit = node.render_annotated(context)
  File "C:\Users\Arthur\coopvote\venv\lib\site-packages\django\template\base.py", line 905, in render_annotated
    return self.render(context)
  File "C:\Users\Arthur\coopvote\venv\lib\site-packages\django\template\defaulttags.py", line 446, in render
    url = reverse(view_name, args=args, kwargs=kwargs, current_app=current_app)
  File "C:\Users\Arthur\coopvote\venv\lib\site-packages\django\urls\base.py", line 86, in reverse
    return resolver._reverse_with_prefix(view, prefix, *args, **kwargs)
  File "C:\Users\Arthur\coopvote\venv\lib\site-packages\django\urls\resolvers.py", line 694, in _reverse_with_prefix
    raise NoReverseMatch(msg)
django.urls.exceptions.NoReverseMatch: Reverse for 'ref_depouillement' not found. 'ref_depouillement' is not a valid view function or pattern name.
"GET /voteadmin_depouillement/622a744b11c44ae44693bd5cd67dc3f3679442b6472f71a320da90c4 HTTP/1.1" 500 172668
Internal Server Error: /voteadmin_depouillement/622a744b11c44ae44693bd5cd67dc3f3679442b6472f71a320da90c4
Traceback (most recent call last):
  File "C:\Users\Arthur\coopvote\venv\lib\site-packages\django\core\handlers\exception.py", line 47, in inner
    response = get_response(request)
  File "C:\Users\Arthur\coopvote\venv\lib\site-packages\django\core\handlers\base.py", line 181, in _get_response
    response = wrapped_callback(request, *callback_args, **callback_kwargs)
  File "C:\Users\Arthur\coopvote\newref\views.py", line 270, in voteadmin_depouillement
    return render(request, template, context)
  File "C:\Users\Arthur\coopvote\venv\lib\site-packages\django\shortcuts.py", line 19, in render
    content = loader.render_to_string(template_name, context, request, using=using)
  File "C:\Users\Arthur\coopvote\venv\lib\site-packages\django\template\loader.py", line 62, in render_to_string
    return template.render(context, request)
  File "C:\Users\Arthur\coopvote\venv\lib\site-packages\django\template\backends\django.py", line 61, in render
    return self.template.render(context)
  File "C:\Users\Arthur\coopvote\venv\lib\site-packages\django\template\base.py", line 170, in render
    return self._render(context)
  File "C:\Users\Arthur\coopvote\venv\lib\site-packages\django\template\base.py", line 162, in _render
    return self.nodelist.render(context)
  File "C:\Users\Arthur\coopvote\venv\lib\site-packages\django\template\base.py", line 938, in render
    bit = node.render_annotated(context)
  File "C:\Users\Arthur\coopvote\venv\lib\site-packages\django\template\base.py", line 905, in render_annotated
    return self.render(context)
  File "C:\Users\Arthur\coopvote\venv\lib\site-packages\django\template\loader_tags.py", line 150, in render
    return compiled_parent._render(context)
  File "C:\Users\Arthur\coopvote\venv\lib\site-packages\django\template\base.py", line 162, in _render
    return self.nodelist.render(context)
  File "C:\Users\Arthur\coopvote\venv\lib\site-packages\django\template\base.py", line 938, in render
    bit = node.render_annotated(context)
  File "C:\Users\Arthur\coopvote\venv\lib\site-packages\django\template\base.py", line 905, in render_annotated
    return self.render(context)
  File "C:\Users\Arthur\coopvote\venv\lib\site-packages\django\templatetags\i18n.py", line 194, in render
    output = self.nodelist.render(context)
  File "C:\Users\Arthur\coopvote\venv\lib\site-packages\django\template\base.py", line 938, in render
    bit = node.render_annotated(context)
  File "C:\Users\Arthur\coopvote\venv\lib\site-packages\django\template\base.py", line 905, in render_annotated
    return self.render(context)
  File "C:\Users\Arthur\coopvote\venv\lib\site-packages\django\template\loader_tags.py", line 62, in render
    result = block.nodelist.render(context)
  File "C:\Users\Arthur\coopvote\venv\lib\site-packages\django\template\base.py", line 938, in render
    bit = node.render_annotated(context)
  File "C:\Users\Arthur\coopvote\venv\lib\site-packages\django\template\base.py", line 905, in render_annotated
    return self.render(context)
  File "C:\Users\Arthur\coopvote\venv\lib\site-packages\django\template\defaulttags.py", line 446, in render
    url = reverse(view_name, args=args, kwargs=kwargs, current_app=current_app)
  File "C:\Users\Arthur\coopvote\venv\lib\site-packages\django\urls\base.py", line 86, in reverse
    return resolver._reverse_with_prefix(view, prefix, *args, **kwargs)
  File "C:\Users\Arthur\coopvote\venv\lib\site-packages\django\urls\resolvers.py", line 694, in _reverse_with_prefix
    raise NoReverseMatch(msg)
django.urls.exceptions.NoReverseMatch: Reverse for 'ref_results' with arguments '('622a744b11c44ae44693bd5cd67dc3f3679442b6472f71a320da90c4',)' not found. 1 pattern(s) tried: ['ref_results/(?P<id_ref>[0-9]+)$']
"GET /voteadmin_depouillement/622a744b11c44ae44693bd5cd67dc3f3679442b6472f71a320da90c4 HTTP/1.1" 500 178197
Internal Server Error: /voteadmin_depouillement/622a744b11c44ae44693bd5cd67dc3f3679442b6472f71a320da90c4
Traceback (most recent call last):
  File "C:\Users\Arthur\coopvote\venv\lib\site-packages\django\core\handlers\exception.py", line 47, in inner
    response = get_response(request)
  File "C:\Users\Arthur\coopvote\venv\lib\site-packages\django\core\handlers\base.py", line 181, in _get_response
    response = wrapped_callback(request, *callback_args, **callback_kwargs)
  File "C:\Users\Arthur\coopvote\newref\views.py", line 270, in voteadmin_depouillement
    return render(request, template, context)
  File "C:\Users\Arthur\coopvote\venv\lib\site-packages\django\shortcuts.py", line 19, in render
    content = loader.render_to_string(template_name, context, request, using=using)
  File "C:\Users\Arthur\coopvote\venv\lib\site-packages\django\template\loader.py", line 62, in render_to_string
    return template.render(context, request)
  File "C:\Users\Arthur\coopvote\venv\lib\site-packages\django\template\backends\django.py", line 61, in render
    return self.template.render(context)
  File "C:\Users\Arthur\coopvote\venv\lib\site-packages\django\template\base.py", line 170, in render
    return self._render(context)
  File "C:\Users\Arthur\coopvote\venv\lib\site-packages\django\template\base.py", line 162, in _render
    return self.nodelist.render(context)
  File "C:\Users\Arthur\coopvote\venv\lib\site-packages\django\template\base.py", line 938, in render
    bit = node.render_annotated(context)
  File "C:\Users\Arthur\coopvote\venv\lib\site-packages\django\template\base.py", line 905, in render_annotated
    return self.render(context)
  File "C:\Users\Arthur\coopvote\venv\lib\site-packages\django\template\loader_tags.py", line 150, in render
    return compiled_parent._render(context)
  File "C:\Users\Arthur\coopvote\venv\lib\site-packages\django\template\base.py", line 162, in _render
    return self.nodelist.render(context)
  File "C:\Users\Arthur\coopvote\venv\lib\site-packages\django\template\base.py", line 938, in render
    bit = node.render_annotated(context)
  File "C:\Users\Arthur\coopvote\venv\lib\site-packages\django\template\base.py", line 905, in render_annotated
    return self.render(context)
  File "C:\Users\Arthur\coopvote\venv\lib\site-packages\django\templatetags\i18n.py", line 194, in render
    output = self.nodelist.render(context)
  File "C:\Users\Arthur\coopvote\venv\lib\site-packages\django\template\base.py", line 938, in render
    bit = node.render_annotated(context)
  File "C:\Users\Arthur\coopvote\venv\lib\site-packages\django\template\base.py", line 905, in render_annotated
    return self.render(context)
  File "C:\Users\Arthur\coopvote\venv\lib\site-packages\django\template\loader_tags.py", line 62, in render
    result = block.nodelist.render(context)
  File "C:\Users\Arthur\coopvote\venv\lib\site-packages\django\template\base.py", line 938, in render
    bit = node.render_annotated(context)
  File "C:\Users\Arthur\coopvote\venv\lib\site-packages\django\template\base.py", line 905, in render_annotated
    return self.render(context)
  File "C:\Users\Arthur\coopvote\venv\lib\site-packages\django\template\defaulttags.py", line 446, in render
    url = reverse(view_name, args=args, kwargs=kwargs, current_app=current_app)
  File "C:\Users\Arthur\coopvote\venv\lib\site-packages\django\urls\base.py", line 86, in reverse
    return resolver._reverse_with_prefix(view, prefix, *args, **kwargs)
  File "C:\Users\Arthur\coopvote\venv\lib\site-packages\django\urls\resolvers.py", line 694, in _reverse_with_prefix
    raise NoReverseMatch(msg)
django.urls.exceptions.NoReverseMatch: Reverse for 'ref_results' with arguments '('622a744b11c44ae44693bd5cd67dc3f3679442b6472f71a320da90c4',)' not found. 1 pattern(s) tried: ['ref_results/(?P<id_ref>[0-9]+)$']
"GET /voteadmin_depouillement/622a744b11c44ae44693bd5cd67dc3f3679442b6472f71a320da90c4 HTTP/1.1" 500 178407
Internal Server Error: /ref_results/2
Traceback (most recent call last):
  File "C:\Users\Arthur\coopvote\venv\lib\site-packages\django\core\handlers\exception.py", line 47, in inner
    response = get_response(request)
  File "C:\Users\Arthur\coopvote\venv\lib\site-packages\django\core\handlers\base.py", line 188, in _get_response
    self.check_response(response, callback)
  File "C:\Users\Arthur\coopvote\venv\lib\site-packages\django\core\handlers\base.py", line 309, in check_response
    raise ValueError(
ValueError: The view newref.views.ref_results didn't return an HttpResponse object. It returned None instead.
"GET /ref_results/2 HTTP/1.1" 500 68895
Internal Server Error: /voteresults/3
Traceback (most recent call last):
  File "C:\Users\Arthur\coopvote\venv\lib\site-packages\django\template\base.py", line 454, in parse
    command = token.contents.split()[0]
IndexError: list index out of range

During handling of the above exception, another exception occurred:

Traceback (most recent call last):
  File "C:\Users\Arthur\coopvote\venv\lib\site-packages\django\core\handlers\exception.py", line 47, in inner
    response = get_response(request)
  File "C:\Users\Arthur\coopvote\venv\lib\site-packages\django\core\handlers\base.py", line 181, in _get_response
    response = wrapped_callback(request, *callback_args, **callback_kwargs)
  File "C:\Users\Arthur\coopvote\newref\views.py", line 411, in voteresults
    return render(request, template, context)
  File "C:\Users\Arthur\coopvote\venv\lib\site-packages\django\shortcuts.py", line 19, in render
    content = loader.render_to_string(template_name, context, request, using=using)
  File "C:\Users\Arthur\coopvote\venv\lib\site-packages\django\template\loader.py", line 61, in render_to_string
    template = get_template(template_name, using=using)
  File "C:\Users\Arthur\coopvote\venv\lib\site-packages\django\template\loader.py", line 15, in get_template
    return engine.get_template(template_name)
  File "C:\Users\Arthur\coopvote\venv\lib\site-packages\django\template\backends\django.py", line 34, in get_template
    return Template(self.engine.get_template(template_name), self)
  File "C:\Users\Arthur\coopvote\venv\lib\site-packages\django\template\engine.py", line 143, in get_template
    template, origin = self.find_template(template_name)
  File "C:\Users\Arthur\coopvote\venv\lib\site-packages\django\template\engine.py", line 125, in find_template
    template = loader.get_template(name, skip=skip)
  File "C:\Users\Arthur\coopvote\venv\lib\site-packages\django\template\loaders\base.py", line 29, in get_template
    return Template(
  File "C:\Users\Arthur\coopvote\venv\lib\site-packages\django\template\base.py", line 155, in __init__
    self.nodelist = self.compile_nodelist()
  File "C:\Users\Arthur\coopvote\venv\lib\site-packages\django\template\base.py", line 193, in compile_nodelist
    return parser.parse()
  File "C:\Users\Arthur\coopvote\venv\lib\site-packages\django\template\base.py", line 478, in parse
    raise self.error(token, e)
  File "C:\Users\Arthur\coopvote\venv\lib\site-packages\django\template\base.py", line 476, in parse
    compiled_result = compile_func(self, token)
  File "C:\Users\Arthur\coopvote\venv\lib\site-packages\django\template\loader_tags.py", line 278, in do_extends
    nodelist = parser.parse()
  File "C:\Users\Arthur\coopvote\venv\lib\site-packages\django\template\base.py", line 478, in parse
    raise self.error(token, e)
  File "C:\Users\Arthur\coopvote\venv\lib\site-packages\django\template\base.py", line 476, in parse
    compiled_result = compile_func(self, token)
  File "C:\Users\Arthur\coopvote\venv\lib\site-packages\django\template\loader_tags.py", line 216, in do_block
    nodelist = parser.parse(('endblock',))
  File "C:\Users\Arthur\coopvote\venv\lib\site-packages\django\template\base.py", line 478, in parse
    raise self.error(token, e)
  File "C:\Users\Arthur\coopvote\venv\lib\site-packages\django\template\base.py", line 476, in parse
    compiled_result = compile_func(self, token)
  File "C:\Users\Arthur\coopvote\venv\lib\site-packages\django\template\defaulttags.py", line 814, in do_for
    nodelist_loop = parser.parse(('empty', 'endfor',))
  File "C:\Users\Arthur\coopvote\venv\lib\site-packages\django\template\base.py", line 478, in parse
    raise self.error(token, e)
  File "C:\Users\Arthur\coopvote\venv\lib\site-packages\django\template\base.py", line 476, in parse
    compiled_result = compile_func(self, token)
  File "C:\Users\Arthur\coopvote\venv\lib\site-packages\django\template\defaulttags.py", line 814, in do_for
    nodelist_loop = parser.parse(('empty', 'endfor',))
  File "C:\Users\Arthur\coopvote\venv\lib\site-packages\django\template\base.py", line 478, in parse
    raise self.error(token, e)
  File "C:\Users\Arthur\coopvote\venv\lib\site-packages\django\template\base.py", line 476, in parse
    compiled_result = compile_func(self, token)
  File "C:\Users\Arthur\coopvote\venv\lib\site-packages\django\template\defaulttags.py", line 814, in do_for
    nodelist_loop = parser.parse(('empty', 'endfor',))
  File "C:\Users\Arthur\coopvote\venv\lib\site-packages\django\template\base.py", line 478, in parse
    raise self.error(token, e)
  File "C:\Users\Arthur\coopvote\venv\lib\site-packages\django\template\base.py", line 476, in parse
    compiled_result = compile_func(self, token)
  File "C:\Users\Arthur\coopvote\venv\lib\site-packages\django\template\defaulttags.py", line 965, in do_if
    nodelist = parser.parse(('elif', 'else', 'endif'))
  File "C:\Users\Arthur\coopvote\venv\lib\site-packages\django\template\base.py", line 456, in parse
    raise self.error(token, 'Empty block tag on line %d' % token.lineno)
django.template.exceptions.TemplateSyntaxError: Empty block tag on line 25
"GET /voteresults/3 HTTP/1.1" 500 219056
Internal Server Error: /voteresults/3
Traceback (most recent call last):
  File "C:\Users\Arthur\coopvote\venv\lib\site-packages\django\template\base.py", line 470, in parse
    compile_func = self.tags[command]
KeyError: 'endif'

During handling of the above exception, another exception occurred:

Traceback (most recent call last):
  File "C:\Users\Arthur\coopvote\venv\lib\site-packages\django\core\handlers\exception.py", line 47, in inner
    response = get_response(request)
  File "C:\Users\Arthur\coopvote\venv\lib\site-packages\django\core\handlers\base.py", line 181, in _get_response
    response = wrapped_callback(request, *callback_args, **callback_kwargs)
  File "C:\Users\Arthur\coopvote\newref\views.py", line 411, in voteresults
    return render(request, template, context)
  File "C:\Users\Arthur\coopvote\venv\lib\site-packages\django\shortcuts.py", line 19, in render
    content = loader.render_to_string(template_name, context, request, using=using)
  File "C:\Users\Arthur\coopvote\venv\lib\site-packages\django\template\loader.py", line 61, in render_to_string
    template = get_template(template_name, using=using)
  File "C:\Users\Arthur\coopvote\venv\lib\site-packages\django\template\loader.py", line 15, in get_template
    return engine.get_template(template_name)
  File "C:\Users\Arthur\coopvote\venv\lib\site-packages\django\template\backends\django.py", line 34, in get_template
    return Template(self.engine.get_template(template_name), self)
  File "C:\Users\Arthur\coopvote\venv\lib\site-packages\django\template\engine.py", line 143, in get_template
    template, origin = self.find_template(template_name)
  File "C:\Users\Arthur\coopvote\venv\lib\site-packages\django\template\engine.py", line 125, in find_template
    template = loader.get_template(name, skip=skip)
  File "C:\Users\Arthur\coopvote\venv\lib\site-packages\django\template\loaders\base.py", line 29, in get_template
    return Template(
  File "C:\Users\Arthur\coopvote\venv\lib\site-packages\django\template\base.py", line 155, in __init__
    self.nodelist = self.compile_nodelist()
  File "C:\Users\Arthur\coopvote\venv\lib\site-packages\django\template\base.py", line 193, in compile_nodelist
    return parser.parse()
  File "C:\Users\Arthur\coopvote\venv\lib\site-packages\django\template\base.py", line 478, in parse
    raise self.error(token, e)
  File "C:\Users\Arthur\coopvote\venv\lib\site-packages\django\template\base.py", line 476, in parse
    compiled_result = compile_func(self, token)
  File "C:\Users\Arthur\coopvote\venv\lib\site-packages\django\template\loader_tags.py", line 278, in do_extends
    nodelist = parser.parse()
  File "C:\Users\Arthur\coopvote\venv\lib\site-packages\django\template\base.py", line 478, in parse
    raise self.error(token, e)
  File "C:\Users\Arthur\coopvote\venv\lib\site-packages\django\template\base.py", line 476, in parse
    compiled_result = compile_func(self, token)
  File "C:\Users\Arthur\coopvote\venv\lib\site-packages\django\template\loader_tags.py", line 216, in do_block
    nodelist = parser.parse(('endblock',))
  File "C:\Users\Arthur\coopvote\venv\lib\site-packages\django\template\base.py", line 478, in parse
    raise self.error(token, e)
  File "C:\Users\Arthur\coopvote\venv\lib\site-packages\django\template\base.py", line 476, in parse
    compiled_result = compile_func(self, token)
  File "C:\Users\Arthur\coopvote\venv\lib\site-packages\django\template\defaulttags.py", line 814, in do_for
    nodelist_loop = parser.parse(('empty', 'endfor',))
  File "C:\Users\Arthur\coopvote\venv\lib\site-packages\django\template\base.py", line 478, in parse
    raise self.error(token, e)
  File "C:\Users\Arthur\coopvote\venv\lib\site-packages\django\template\base.py", line 476, in parse
    compiled_result = compile_func(self, token)
  File "C:\Users\Arthur\coopvote\venv\lib\site-packages\django\template\defaulttags.py", line 814, in do_for
    nodelist_loop = parser.parse(('empty', 'endfor',))
  File "C:\Users\Arthur\coopvote\venv\lib\site-packages\django\template\base.py", line 478, in parse
    raise self.error(token, e)
  File "C:\Users\Arthur\coopvote\venv\lib\site-packages\django\template\base.py", line 476, in parse
    compiled_result = compile_func(self, token)
  File "C:\Users\Arthur\coopvote\venv\lib\site-packages\django\template\defaulttags.py", line 814, in do_for
    nodelist_loop = parser.parse(('empty', 'endfor',))
  File "C:\Users\Arthur\coopvote\venv\lib\site-packages\django\template\base.py", line 472, in parse
    self.invalid_block_tag(token, command, parse_until)
  File "C:\Users\Arthur\coopvote\venv\lib\site-packages\django\template\base.py", line 522, in invalid_block_tag
    raise self.error(
django.template.exceptions.TemplateSyntaxError: Invalid block tag on line 25: 'endif', expected 'empty' or 'endfor'. Did you forget to register or load this tag?
"GET /voteresults/3 HTTP/1.1" 500 209735
Internal Server Error: /voteadmin_depouillement/90a3ed9e32b2aaf4c61c410eb925426119e1a9dc53d4286ade99a809
Traceback (most recent call last):
  File "C:\Users\Arthur\coopvote\venv\lib\site-packages\django\core\handlers\exception.py", line 47, in inner
    response = get_response(request)
  File "C:\Users\Arthur\coopvote\venv\lib\site-packages\django\core\handlers\base.py", line 181, in _get_response
    response = wrapped_callback(request, *callback_args, **callback_kwargs)
  File "C:\Users\Arthur\coopvote\newref\views.py", line 303, in voteadmin_depouillement
    ref.valid_rawvotes =Rawvote.objects.filter(ref = ref).filter(json!=None)
NameError: name 'json' is not defined
"GET /voteadmin_depouillement/90a3ed9e32b2aaf4c61c410eb925426119e1a9dc53d4286ade99a809 HTTP/1.1" 500 69131
Internal Server Error: /voteadmin_depouillement/90a3ed9e32b2aaf4c61c410eb925426119e1a9dc53d4286ade99a809
Traceback (most recent call last):
  File "C:\Users\Arthur\coopvote\venv\lib\site-packages\django\core\handlers\exception.py", line 47, in inner
    response = get_response(request)
  File "C:\Users\Arthur\coopvote\venv\lib\site-packages\django\core\handlers\base.py", line 181, in _get_response
    response = wrapped_callback(request, *callback_args, **callback_kwargs)
  File "C:\Users\Arthur\coopvote\newref\views.py", line 303, in voteadmin_depouillement
    ref.valid_rawvotes = Rawvote.objects.filter(ref = ref).filter(json != None)
NameError: name 'json' is not defined
"GET /voteadmin_depouillement/90a3ed9e32b2aaf4c61c410eb925426119e1a9dc53d4286ade99a809 HTTP/1.1" 500 69137
Internal Server Error: /voteadmin_depouillement/90a3ed9e32b2aaf4c61c410eb925426119e1a9dc53d4286ade99a809
Traceback (most recent call last):
  File "C:\Users\Arthur\coopvote\venv\lib\site-packages\django\core\handlers\exception.py", line 47, in inner
    response = get_response(request)
  File "C:\Users\Arthur\coopvote\venv\lib\site-packages\django\core\handlers\base.py", line 181, in _get_response
    response = wrapped_callback(request, *callback_args, **callback_kwargs)
  File "C:\Users\Arthur\coopvote\newref\views.py", line 303, in voteadmin_depouillement
    ref.valid_rawvotes = Rawvote.objects.filter(ref = ref).filter(json != None)
NameError: name 'json' is not defined
"GET /voteadmin_depouillement/90a3ed9e32b2aaf4c61c410eb925426119e1a9dc53d4286ade99a809 HTTP/1.1" 500 69137
Internal Server Error: /preview_bulletin/90a3ed9e32b2aaf4c61c410eb925426119e1a9dc53d4286ade99a809
Traceback (most recent call last):
  File "C:\Users\Arthur\coopvote\venv\lib\site-packages\django\core\handlers\exception.py", line 47, in inner
    response = get_response(request)
  File "C:\Users\Arthur\coopvote\venv\lib\site-packages\django\core\handlers\base.py", line 181, in _get_response
    response = wrapped_callback(request, *callback_args, **callback_kwargs)
  File "C:\Users\Arthur\coopvote\newref\views.py", line 232, in preview_bulletin
    rawvote = Rawvote.objects.filter(ref=ref).filter(email="test@exemple.fr")[0]
  File "C:\Users\Arthur\coopvote\venv\lib\site-packages\django\db\models\query.py", line 318, in __getitem__
    return qs._result_cache[0]
IndexError: list index out of range
"GET /preview_bulletin/90a3ed9e32b2aaf4c61c410eb925426119e1a9dc53d4286ade99a809 HTTP/1.1" 500 72774
Internal Server Error: /voteadmin_depouillement/35f757ad7f998eb6dd3dd1cd3b5c6de97348b84a951f13de25355177
Traceback (most recent call last):
  File "C:\Users\Arthur\coopvote\venv\lib\site-packages\django\core\handlers\exception.py", line 47, in inner
    response = get_response(request)
  File "C:\Users\Arthur\coopvote\venv\lib\site-packages\django\core\handlers\base.py", line 181, in _get_response
    response = wrapped_callback(request, *callback_args, **callback_kwargs)
  File "C:\Users\Arthur\coopvote\newref\views.py", line 304, in voteadmin_depouillement
    print(datetime.date.today())
AttributeError: 'method_descriptor' object has no attribute 'today'
"GET /voteadmin_depouillement/35f757ad7f998eb6dd3dd1cd3b5c6de97348b84a951f13de25355177 HTTP/1.1" 500 69208
Internal Server Error: /voteadmin_depouillement/35f757ad7f998eb6dd3dd1cd3b5c6de97348b84a951f13de25355177
Traceback (most recent call last):
  File "C:\Users\Arthur\coopvote\venv\lib\site-packages\django\core\handlers\exception.py", line 47, in inner
    response = get_response(request)
  File "C:\Users\Arthur\coopvote\venv\lib\site-packages\django\core\handlers\base.py", line 181, in _get_response
    response = wrapped_callback(request, *callback_args, **callback_kwargs)
  File "C:\Users\Arthur\coopvote\newref\views.py", line 308, in voteadmin_depouillement
    if datetime.today().strftime('%Y-%m-%d') < ref.start:
TypeError: '<' not supported between instances of 'str' and 'datetime.date'
"GET /voteadmin_depouillement/35f757ad7f998eb6dd3dd1cd3b5c6de97348b84a951f13de25355177 HTTP/1.1" 500 69365
Internal Server Error: /voteadmin_depouillement/35f757ad7f998eb6dd3dd1cd3b5c6de97348b84a951f13de25355177
Traceback (most recent call last):
  File "C:\Users\Arthur\coopvote\venv\lib\site-packages\django\core\handlers\exception.py", line 47, in inner
    response = get_response(request)
  File "C:\Users\Arthur\coopvote\venv\lib\site-packages\django\core\handlers\base.py", line 181, in _get_response
    response = wrapped_callback(request, *callback_args, **callback_kwargs)
  File "C:\Users\Arthur\coopvote\newref\views.py", line 308, in voteadmin_depouillement
    if datetime.today() < ref.start:
TypeError: can't compare datetime.datetime to datetime.date
"GET /voteadmin_depouillement/35f757ad7f998eb6dd3dd1cd3b5c6de97348b84a951f13de25355177 HTTP/1.1" 500 69127
Internal Server Error: /
Traceback (most recent call last):
  File "/usr/local/lib/python3.9/site-packages/django/db/backends/utils.py", line 84, in _execute
    return self.cursor.execute(sql, params)
psycopg2.errors.UndefinedTable: relation "newref_ref" does not exist
LINE 1: ..., "newref_ref"."hash", "newref_ref"."status" FROM "newref_re...
                                                             ^


The above exception was the direct cause of the following exception:

Traceback (most recent call last):
  File "/usr/local/lib/python3.9/site-packages/django/core/handlers/exception.py", line 47, in inner
    response = get_response(request)
  File "/usr/local/lib/python3.9/site-packages/django/core/handlers/base.py", line 181, in _get_response
    response = wrapped_callback(request, *callback_args, **callback_kwargs)
  File "/usr/src/app/newref/views.py", line 57, in refs
    return render(request, template, context)
  File "/usr/local/lib/python3.9/site-packages/django/shortcuts.py", line 19, in render
    content = loader.render_to_string(template_name, context, request, using=using)
  File "/usr/local/lib/python3.9/site-packages/django/template/loader.py", line 62, in render_to_string
    return template.render(context, request)
  File "/usr/local/lib/python3.9/site-packages/django/template/backends/django.py", line 61, in render
    return self.template.render(context)
  File "/usr/local/lib/python3.9/site-packages/django/template/base.py", line 170, in render
    return self._render(context)
  File "/usr/local/lib/python3.9/site-packages/django/template/base.py", line 162, in _render
    return self.nodelist.render(context)
  File "/usr/local/lib/python3.9/site-packages/django/template/base.py", line 938, in render
    bit = node.render_annotated(context)
  File "/usr/local/lib/python3.9/site-packages/django/template/base.py", line 905, in render_annotated
    return self.render(context)
  File "/usr/local/lib/python3.9/site-packages/django/template/loader_tags.py", line 150, in render
    return compiled_parent._render(context)
  File "/usr/local/lib/python3.9/site-packages/django/template/base.py", line 162, in _render
    return self.nodelist.render(context)
  File "/usr/local/lib/python3.9/site-packages/django/template/base.py", line 938, in render
    bit = node.render_annotated(context)
  File "/usr/local/lib/python3.9/site-packages/django/template/base.py", line 905, in render_annotated
    return self.render(context)
  File "/usr/local/lib/python3.9/site-packages/django/templatetags/i18n.py", line 194, in render
    output = self.nodelist.render(context)
  File "/usr/local/lib/python3.9/site-packages/django/template/base.py", line 938, in render
    bit = node.render_annotated(context)
  File "/usr/local/lib/python3.9/site-packages/django/template/base.py", line 905, in render_annotated
    return self.render(context)
  File "/usr/local/lib/python3.9/site-packages/django/template/loader_tags.py", line 62, in render
    result = block.nodelist.render(context)
  File "/usr/local/lib/python3.9/site-packages/django/template/base.py", line 938, in render
    bit = node.render_annotated(context)
  File "/usr/local/lib/python3.9/site-packages/django/template/base.py", line 905, in render_annotated
    return self.render(context)
  File "/usr/local/lib/python3.9/site-packages/django/template/defaulttags.py", line 168, in render
    len_values = len(values)
  File "/usr/local/lib/python3.9/site-packages/django/db/models/query.py", line 262, in __len__
    self._fetch_all()
  File "/usr/local/lib/python3.9/site-packages/django/db/models/query.py", line 1324, in _fetch_all
    self._result_cache = list(self._iterable_class(self))
  File "/usr/local/lib/python3.9/site-packages/django/db/models/query.py", line 51, in __iter__
    results = compiler.execute_sql(chunked_fetch=self.chunked_fetch, chunk_size=self.chunk_size)
  File "/usr/local/lib/python3.9/site-packages/django/db/models/sql/compiler.py", line 1169, in execute_sql
    cursor.execute(sql, params)
  File "/usr/local/lib/python3.9/site-packages/django/db/backends/utils.py", line 98, in execute
    return super().execute(sql, params)
  File "/usr/local/lib/python3.9/site-packages/django/db/backends/utils.py", line 66, in execute
    return self._execute_with_wrappers(sql, params, many=False, executor=self._execute)
  File "/usr/local/lib/python3.9/site-packages/django/db/backends/utils.py", line 75, in _execute_with_wrappers
    return executor(sql, params, many, context)
  File "/usr/local/lib/python3.9/site-packages/django/db/backends/utils.py", line 84, in _execute
    return self.cursor.execute(sql, params)
  File "/usr/local/lib/python3.9/site-packages/django/db/utils.py", line 90, in __exit__
    raise dj_exc_value.with_traceback(traceback) from exc_value
  File "/usr/local/lib/python3.9/site-packages/django/db/backends/utils.py", line 84, in _execute
    return self.cursor.execute(sql, params)
django.db.utils.ProgrammingError: relation "newref_ref" does not exist
LINE 1: ..., "newref_ref"."hash", "newref_ref"."status" FROM "newref_re...
                                                             ^

"GET / HTTP/1.1" 500 215293
Internal Server Error: /
Traceback (most recent call last):
  File "/usr/local/lib/python3.9/site-packages/django/db/backends/utils.py", line 84, in _execute
    return self.cursor.execute(sql, params)
psycopg2.errors.UndefinedTable: relation "newref_ref" does not exist
LINE 1: ..., "newref_ref"."hash", "newref_ref"."status" FROM "newref_re...
                                                             ^


The above exception was the direct cause of the following exception:

Traceback (most recent call last):
  File "/usr/local/lib/python3.9/site-packages/django/core/handlers/exception.py", line 47, in inner
    response = get_response(request)
  File "/usr/local/lib/python3.9/site-packages/django/core/handlers/base.py", line 181, in _get_response
    response = wrapped_callback(request, *callback_args, **callback_kwargs)
  File "/usr/src/app/newref/views.py", line 57, in refs
    return render(request, template, context)
  File "/usr/local/lib/python3.9/site-packages/django/shortcuts.py", line 19, in render
    content = loader.render_to_string(template_name, context, request, using=using)
  File "/usr/local/lib/python3.9/site-packages/django/template/loader.py", line 62, in render_to_string
    return template.render(context, request)
  File "/usr/local/lib/python3.9/site-packages/django/template/backends/django.py", line 61, in render
    return self.template.render(context)
  File "/usr/local/lib/python3.9/site-packages/django/template/base.py", line 170, in render
    return self._render(context)
  File "/usr/local/lib/python3.9/site-packages/django/template/base.py", line 162, in _render
    return self.nodelist.render(context)
  File "/usr/local/lib/python3.9/site-packages/django/template/base.py", line 938, in render
    bit = node.render_annotated(context)
  File "/usr/local/lib/python3.9/site-packages/django/template/base.py", line 905, in render_annotated
    return self.render(context)
  File "/usr/local/lib/python3.9/site-packages/django/template/loader_tags.py", line 150, in render
    return compiled_parent._render(context)
  File "/usr/local/lib/python3.9/site-packages/django/template/base.py", line 162, in _render
    return self.nodelist.render(context)
  File "/usr/local/lib/python3.9/site-packages/django/template/base.py", line 938, in render
    bit = node.render_annotated(context)
  File "/usr/local/lib/python3.9/site-packages/django/template/base.py", line 905, in render_annotated
    return self.render(context)
  File "/usr/local/lib/python3.9/site-packages/django/templatetags/i18n.py", line 194, in render
    output = self.nodelist.render(context)
  File "/usr/local/lib/python3.9/site-packages/django/template/base.py", line 938, in render
    bit = node.render_annotated(context)
  File "/usr/local/lib/python3.9/site-packages/django/template/base.py", line 905, in render_annotated
    return self.render(context)
  File "/usr/local/lib/python3.9/site-packages/django/template/loader_tags.py", line 62, in render
    result = block.nodelist.render(context)
  File "/usr/local/lib/python3.9/site-packages/django/template/base.py", line 938, in render
    bit = node.render_annotated(context)
  File "/usr/local/lib/python3.9/site-packages/django/template/base.py", line 905, in render_annotated
    return self.render(context)
  File "/usr/local/lib/python3.9/site-packages/django/template/defaulttags.py", line 168, in render
    len_values = len(values)
  File "/usr/local/lib/python3.9/site-packages/django/db/models/query.py", line 262, in __len__
    self._fetch_all()
  File "/usr/local/lib/python3.9/site-packages/django/db/models/query.py", line 1324, in _fetch_all
    self._result_cache = list(self._iterable_class(self))
  File "/usr/local/lib/python3.9/site-packages/django/db/models/query.py", line 51, in __iter__
    results = compiler.execute_sql(chunked_fetch=self.chunked_fetch, chunk_size=self.chunk_size)
  File "/usr/local/lib/python3.9/site-packages/django/db/models/sql/compiler.py", line 1169, in execute_sql
    cursor.execute(sql, params)
  File "/usr/local/lib/python3.9/site-packages/django/db/backends/utils.py", line 98, in execute
    return super().execute(sql, params)
  File "/usr/local/lib/python3.9/site-packages/django/db/backends/utils.py", line 66, in execute
    return self._execute_with_wrappers(sql, params, many=False, executor=self._execute)
  File "/usr/local/lib/python3.9/site-packages/django/db/backends/utils.py", line 75, in _execute_with_wrappers
    return executor(sql, params, many, context)
  File "/usr/local/lib/python3.9/site-packages/django/db/backends/utils.py", line 84, in _execute
    return self.cursor.execute(sql, params)
  File "/usr/local/lib/python3.9/site-packages/django/db/utils.py", line 90, in __exit__
    raise dj_exc_value.with_traceback(traceback) from exc_value
  File "/usr/local/lib/python3.9/site-packages/django/db/backends/utils.py", line 84, in _execute
    return self.cursor.execute(sql, params)
django.db.utils.ProgrammingError: relation "newref_ref" does not exist
LINE 1: ..., "newref_ref"."hash", "newref_ref"."status" FROM "newref_re...
                                                             ^

"GET / HTTP/1.1" 500 215538
Internal Server Error: /voteadmin_depouillement/97fea796a32aa21dde1a1d29b9221624b53bde9dc6eb1cde25138d82
Traceback (most recent call last):
  File "/usr/local/lib/python3.9/site-packages/django/core/handlers/exception.py", line 47, in inner
    response = get_response(request)
  File "/usr/local/lib/python3.9/site-packages/django/core/handlers/base.py", line 181, in _get_response
    response = wrapped_callback(request, *callback_args, **callback_kwargs)
  File "/usr/src/app/newref/views.py", line 305, in voteadmin_depouillement
    if today<ref.start:
TypeError: '<' not supported between instances of 'datetime.date' and 'NoneType'
"GET /voteadmin_depouillement/97fea796a32aa21dde1a1d29b9221624b53bde9dc6eb1cde25138d82 HTTP/1.1" 500 61312
Internal Server Error: /
Traceback (most recent call last):
  File "C:\Users\Arthur\AppData\Local\Programs\Python\Python39\lib\site-packages\django\db\backends\utils.py", line 84, in _execute
    return self.cursor.execute(sql, params)
  File "C:\Users\Arthur\AppData\Local\Programs\Python\Python39\lib\site-packages\django\db\backends\sqlite3\base.py", line 423, in execute
    return Database.Cursor.execute(self, query, params)
sqlite3.OperationalError: table newref_ref has no column named email_use_tls

The above exception was the direct cause of the following exception:

Traceback (most recent call last):
  File "C:\Users\Arthur\AppData\Local\Programs\Python\Python39\lib\site-packages\django\core\handlers\exception.py", line 47, in inner
    response = get_response(request)
  File "C:\Users\Arthur\AppData\Local\Programs\Python\Python39\lib\site-packages\django\core\handlers\base.py", line 181, in _get_response
    response = wrapped_callback(request, *callback_args, **callback_kwargs)
  File "C:\Users\Arthur\coopvote\app\newref\views.py", line 36, in refs
    ref.save()
  File "C:\Users\Arthur\AppData\Local\Programs\Python\Python39\lib\site-packages\django\db\models\base.py", line 726, in save
    self.save_base(using=using, force_insert=force_insert,
  File "C:\Users\Arthur\AppData\Local\Programs\Python\Python39\lib\site-packages\django\db\models\base.py", line 763, in save_base
    updated = self._save_table(
  File "C:\Users\Arthur\AppData\Local\Programs\Python\Python39\lib\site-packages\django\db\models\base.py", line 868, in _save_table
    results = self._do_insert(cls._base_manager, using, fields, returning_fields, raw)
  File "C:\Users\Arthur\AppData\Local\Programs\Python\Python39\lib\site-packages\django\db\models\base.py", line 906, in _do_insert
    return manager._insert(
  File "C:\Users\Arthur\AppData\Local\Programs\Python\Python39\lib\site-packages\django\db\models\manager.py", line 85, in manager_method
    return getattr(self.get_queryset(), name)(*args, **kwargs)
  File "C:\Users\Arthur\AppData\Local\Programs\Python\Python39\lib\site-packages\django\db\models\query.py", line 1270, in _insert
    return query.get_compiler(using=using).execute_sql(returning_fields)
  File "C:\Users\Arthur\AppData\Local\Programs\Python\Python39\lib\site-packages\django\db\models\sql\compiler.py", line 1410, in execute_sql
    cursor.execute(sql, params)
  File "C:\Users\Arthur\AppData\Local\Programs\Python\Python39\lib\site-packages\django\db\backends\utils.py", line 66, in execute
    return self._execute_with_wrappers(sql, params, many=False, executor=self._execute)
  File "C:\Users\Arthur\AppData\Local\Programs\Python\Python39\lib\site-packages\django\db\backends\utils.py", line 75, in _execute_with_wrappers
    return executor(sql, params, many, context)
  File "C:\Users\Arthur\AppData\Local\Programs\Python\Python39\lib\site-packages\django\db\backends\utils.py", line 84, in _execute
    return self.cursor.execute(sql, params)
  File "C:\Users\Arthur\AppData\Local\Programs\Python\Python39\lib\site-packages\django\db\utils.py", line 90, in __exit__
    raise dj_exc_value.with_traceback(traceback) from exc_value
  File "C:\Users\Arthur\AppData\Local\Programs\Python\Python39\lib\site-packages\django\db\backends\utils.py", line 84, in _execute
    return self.cursor.execute(sql, params)
  File "C:\Users\Arthur\AppData\Local\Programs\Python\Python39\lib\site-packages\django\db\backends\sqlite3\base.py", line 423, in execute
    return Database.Cursor.execute(self, query, params)
django.db.utils.OperationalError: table newref_ref has no column named email_use_tls
"POST / HTTP/1.1" 500 145
Internal Server Error: /
Traceback (most recent call last):
  File "C:\Users\Arthur\AppData\Local\Programs\Python\Python39\lib\site-packages\django\db\backends\utils.py", line 84, in _execute
    return self.cursor.execute(sql, params)
  File "C:\Users\Arthur\AppData\Local\Programs\Python\Python39\lib\site-packages\django\db\backends\sqlite3\base.py", line 423, in execute
    return Database.Cursor.execute(self, query, params)
sqlite3.OperationalError: no such column: newref_ref.email_use_tls

The above exception was the direct cause of the following exception:

Traceback (most recent call last):
  File "C:\Users\Arthur\AppData\Local\Programs\Python\Python39\lib\site-packages\django\core\handlers\exception.py", line 47, in inner
    response = get_response(request)
  File "C:\Users\Arthur\AppData\Local\Programs\Python\Python39\lib\site-packages\django\core\handlers\base.py", line 181, in _get_response
    response = wrapped_callback(request, *callback_args, **callback_kwargs)
  File "C:\Users\Arthur\coopvote\app\newref\views.py", line 57, in refs
    return render(request, template, context)
  File "C:\Users\Arthur\AppData\Local\Programs\Python\Python39\lib\site-packages\django\shortcuts.py", line 19, in render
    content = loader.render_to_string(template_name, context, request, using=using)
  File "C:\Users\Arthur\AppData\Local\Programs\Python\Python39\lib\site-packages\django\template\loader.py", line 62, in render_to_string
    return template.render(context, request)
  File "C:\Users\Arthur\AppData\Local\Programs\Python\Python39\lib\site-packages\django\template\backends\django.py", line 61, in render
    return self.template.render(context)
  File "C:\Users\Arthur\AppData\Local\Programs\Python\Python39\lib\site-packages\django\template\base.py", line 170, in render
    return self._render(context)
  File "C:\Users\Arthur\AppData\Local\Programs\Python\Python39\lib\site-packages\django\template\base.py", line 162, in _render
    return self.nodelist.render(context)
  File "C:\Users\Arthur\AppData\Local\Programs\Python\Python39\lib\site-packages\django\template\base.py", line 938, in render
    bit = node.render_annotated(context)
  File "C:\Users\Arthur\AppData\Local\Programs\Python\Python39\lib\site-packages\django\template\base.py", line 905, in render_annotated
    return self.render(context)
  File "C:\Users\Arthur\AppData\Local\Programs\Python\Python39\lib\site-packages\django\template\loader_tags.py", line 150, in render
    return compiled_parent._render(context)
  File "C:\Users\Arthur\AppData\Local\Programs\Python\Python39\lib\site-packages\django\template\base.py", line 162, in _render
    return self.nodelist.render(context)
  File "C:\Users\Arthur\AppData\Local\Programs\Python\Python39\lib\site-packages\django\template\base.py", line 938, in render
    bit = node.render_annotated(context)
  File "C:\Users\Arthur\AppData\Local\Programs\Python\Python39\lib\site-packages\django\template\base.py", line 905, in render_annotated
    return self.render(context)
  File "C:\Users\Arthur\AppData\Local\Programs\Python\Python39\lib\site-packages\django\templatetags\i18n.py", line 194, in render
    output = self.nodelist.render(context)
  File "C:\Users\Arthur\AppData\Local\Programs\Python\Python39\lib\site-packages\django\template\base.py", line 938, in render
    bit = node.render_annotated(context)
  File "C:\Users\Arthur\AppData\Local\Programs\Python\Python39\lib\site-packages\django\template\base.py", line 905, in render_annotated
    return self.render(context)
  File "C:\Users\Arthur\AppData\Local\Programs\Python\Python39\lib\site-packages\django\template\loader_tags.py", line 62, in render
    result = block.nodelist.render(context)
  File "C:\Users\Arthur\AppData\Local\Programs\Python\Python39\lib\site-packages\django\template\base.py", line 938, in render
    bit = node.render_annotated(context)
  File "C:\Users\Arthur\AppData\Local\Programs\Python\Python39\lib\site-packages\django\template\base.py", line 905, in render_annotated
    return self.render(context)
  File "C:\Users\Arthur\AppData\Local\Programs\Python\Python39\lib\site-packages\django\template\defaulttags.py", line 168, in render
    len_values = len(values)
  File "C:\Users\Arthur\AppData\Local\Programs\Python\Python39\lib\site-packages\django\db\models\query.py", line 262, in __len__
    self._fetch_all()
  File "C:\Users\Arthur\AppData\Local\Programs\Python\Python39\lib\site-packages\django\db\models\query.py", line 1324, in _fetch_all
    self._result_cache = list(self._iterable_class(self))
  File "C:\Users\Arthur\AppData\Local\Programs\Python\Python39\lib\site-packages\django\db\models\query.py", line 51, in __iter__
    results = compiler.execute_sql(chunked_fetch=self.chunked_fetch, chunk_size=self.chunk_size)
  File "C:\Users\Arthur\AppData\Local\Programs\Python\Python39\lib\site-packages\django\db\models\sql\compiler.py", line 1169, in execute_sql
    cursor.execute(sql, params)
  File "C:\Users\Arthur\AppData\Local\Programs\Python\Python39\lib\site-packages\django\db\backends\utils.py", line 98, in execute
    return super().execute(sql, params)
  File "C:\Users\Arthur\AppData\Local\Programs\Python\Python39\lib\site-packages\django\db\backends\utils.py", line 66, in execute
    return self._execute_with_wrappers(sql, params, many=False, executor=self._execute)
  File "C:\Users\Arthur\AppData\Local\Programs\Python\Python39\lib\site-packages\django\db\backends\utils.py", line 75, in _execute_with_wrappers
    return executor(sql, params, many, context)
  File "C:\Users\Arthur\AppData\Local\Programs\Python\Python39\lib\site-packages\django\db\backends\utils.py", line 84, in _execute
    return self.cursor.execute(sql, params)
  File "C:\Users\Arthur\AppData\Local\Programs\Python\Python39\lib\site-packages\django\db\utils.py", line 90, in __exit__
    raise dj_exc_value.with_traceback(traceback) from exc_value
  File "C:\Users\Arthur\AppData\Local\Programs\Python\Python39\lib\site-packages\django\db\backends\utils.py", line 84, in _execute
    return self.cursor.execute(sql, params)
  File "C:\Users\Arthur\AppData\Local\Programs\Python\Python39\lib\site-packages\django\db\backends\sqlite3\base.py", line 423, in execute
    return Database.Cursor.execute(self, query, params)
django.db.utils.OperationalError: no such column: newref_ref.email_use_tls
"GET / HTTP/1.1" 500 229641
Internal Server Error: /voteadmin_bulletins/4f555b1bb8bc729a665b8892df73119e2ef2eb50dffaf0d5c546cf23
Traceback (most recent call last):
  File "C:\Users\Arthur\AppData\Local\Programs\Python\Python39\lib\site-packages\django\core\handlers\exception.py", line 47, in inner
    response = get_response(request)
  File "C:\Users\Arthur\AppData\Local\Programs\Python\Python39\lib\site-packages\django\core\handlers\base.py", line 181, in _get_response
    response = wrapped_callback(request, *callback_args, **callback_kwargs)
  File "C:\Users\Arthur\coopvote\app\newref\views.py", line 201, in voteadmin_bulletins
    return render(request, template, context)
  File "C:\Users\Arthur\AppData\Local\Programs\Python\Python39\lib\site-packages\django\shortcuts.py", line 19, in render
    content = loader.render_to_string(template_name, context, request, using=using)
  File "C:\Users\Arthur\AppData\Local\Programs\Python\Python39\lib\site-packages\django\template\loader.py", line 62, in render_to_string
    return template.render(context, request)
  File "C:\Users\Arthur\AppData\Local\Programs\Python\Python39\lib\site-packages\django\template\backends\django.py", line 61, in render
    return self.template.render(context)
  File "C:\Users\Arthur\AppData\Local\Programs\Python\Python39\lib\site-packages\django\template\base.py", line 170, in render
    return self._render(context)
  File "C:\Users\Arthur\AppData\Local\Programs\Python\Python39\lib\site-packages\django\template\base.py", line 162, in _render
    return self.nodelist.render(context)
  File "C:\Users\Arthur\AppData\Local\Programs\Python\Python39\lib\site-packages\django\template\base.py", line 938, in render
    bit = node.render_annotated(context)
  File "C:\Users\Arthur\AppData\Local\Programs\Python\Python39\lib\site-packages\django\template\base.py", line 905, in render_annotated
    return self.render(context)
  File "C:\Users\Arthur\AppData\Local\Programs\Python\Python39\lib\site-packages\django\template\loader_tags.py", line 150, in render
    return compiled_parent._render(context)
  File "C:\Users\Arthur\AppData\Local\Programs\Python\Python39\lib\site-packages\django\template\base.py", line 162, in _render
    return self.nodelist.render(context)
  File "C:\Users\Arthur\AppData\Local\Programs\Python\Python39\lib\site-packages\django\template\base.py", line 938, in render
    bit = node.render_annotated(context)
  File "C:\Users\Arthur\AppData\Local\Programs\Python\Python39\lib\site-packages\django\template\base.py", line 905, in render_annotated
    return self.render(context)
  File "C:\Users\Arthur\AppData\Local\Programs\Python\Python39\lib\site-packages\django\templatetags\i18n.py", line 194, in render
    output = self.nodelist.render(context)
  File "C:\Users\Arthur\AppData\Local\Programs\Python\Python39\lib\site-packages\django\template\base.py", line 938, in render
    bit = node.render_annotated(context)
  File "C:\Users\Arthur\AppData\Local\Programs\Python\Python39\lib\site-packages\django\template\base.py", line 905, in render_annotated
    return self.render(context)
  File "C:\Users\Arthur\AppData\Local\Programs\Python\Python39\lib\site-packages\django\template\loader_tags.py", line 62, in render
    result = block.nodelist.render(context)
  File "C:\Users\Arthur\AppData\Local\Programs\Python\Python39\lib\site-packages\django\template\base.py", line 938, in render
    bit = node.render_annotated(context)
  File "C:\Users\Arthur\AppData\Local\Programs\Python\Python39\lib\site-packages\django\template\base.py", line 905, in render_annotated
    return self.render(context)
  File "C:\Users\Arthur\AppData\Local\Programs\Python\Python39\lib\site-packages\django\template\defaulttags.py", line 446, in render
    url = reverse(view_name, args=args, kwargs=kwargs, current_app=current_app)
  File "C:\Users\Arthur\AppData\Local\Programs\Python\Python39\lib\site-packages\django\urls\base.py", line 86, in reverse
    return resolver._reverse_with_prefix(view, prefix, *args, **kwargs)
  File "C:\Users\Arthur\AppData\Local\Programs\Python\Python39\lib\site-packages\django\urls\resolvers.py", line 694, in _reverse_with_prefix
    raise NoReverseMatch(msg)
django.urls.exceptions.NoReverseMatch: Reverse for 'test_email_sending' not found. 'test_email_sending' is not a valid view function or pattern name.
"GET /voteadmin_bulletins/4f555b1bb8bc729a665b8892df73119e2ef2eb50dffaf0d5c546cf23 HTTP/1.1" 500 184363
Internal Server Error: /test_email_sending/4f555b1bb8bc729a665b8892df73119e2ef2eb50dffaf0d5c546cf23
Traceback (most recent call last):
  File "C:\Users\Arthur\AppData\Local\Programs\Python\Python39\lib\site-packages\django\core\handlers\exception.py", line 47, in inner
    response = get_response(request)
  File "C:\Users\Arthur\AppData\Local\Programs\Python\Python39\lib\site-packages\django\core\handlers\base.py", line 181, in _get_response
    response = wrapped_callback(request, *callback_args, **callback_kwargs)
  File "C:\Users\Arthur\coopvote\app\newref\views.py", line 248, in test_email_sending
    from_email=email_host_user,
NameError: name 'email_host_user' is not defined
"POST /test_email_sending/4f555b1bb8bc729a665b8892df73119e2ef2eb50dffaf0d5c546cf23 HTTP/1.1" 500 69600
Internal Server Error: /test_email_sending/4f555b1bb8bc729a665b8892df73119e2ef2eb50dffaf0d5c546cf23
Traceback (most recent call last):
  File "C:\Users\Arthur\AppData\Local\Programs\Python\Python39\lib\site-packages\django\core\handlers\exception.py", line 47, in inner
    response = get_response(request)
  File "C:\Users\Arthur\AppData\Local\Programs\Python\Python39\lib\site-packages\django\core\handlers\base.py", line 181, in _get_response
    response = wrapped_callback(request, *callback_args, **callback_kwargs)
  File "C:\Users\Arthur\coopvote\app\newref\views.py", line 245, in test_email_sending
    email = EmailMessage(
  File "C:\Users\Arthur\AppData\Local\Programs\Python\Python39\lib\site-packages\django\core\mail\message.py", line 203, in __init__
    raise TypeError('"to" argument must be a list or tuple')
TypeError: "to" argument must be a list or tuple
"POST /test_email_sending/4f555b1bb8bc729a665b8892df73119e2ef2eb50dffaf0d5c546cf23 HTTP/1.1" 500 75174
Internal Server Error: /test_email_sending/4f555b1bb8bc729a665b8892df73119e2ef2eb50dffaf0d5c546cf23
Traceback (most recent call last):
  File "C:\Users\Arthur\AppData\Local\Programs\Python\Python39\lib\site-packages\django\core\handlers\exception.py", line 47, in inner
    response = get_response(request)
  File "C:\Users\Arthur\AppData\Local\Programs\Python\Python39\lib\site-packages\django\core\handlers\base.py", line 181, in _get_response
    response = wrapped_callback(request, *callback_args, **callback_kwargs)
  File "C:\Users\Arthur\coopvote\app\newref\views.py", line 256, in test_email_sending
    email.send()
  File "C:\Users\Arthur\AppData\Local\Programs\Python\Python39\lib\site-packages\django\core\mail\message.py", line 284, in send
    return self.get_connection(fail_silently).send_messages([self])
  File "C:\Users\Arthur\AppData\Local\Programs\Python\Python39\lib\site-packages\django\core\mail\backends\smtp.py", line 102, in send_messages
    new_conn_created = self.open()
  File "C:\Users\Arthur\AppData\Local\Programs\Python\Python39\lib\site-packages\django\core\mail\backends\smtp.py", line 69, in open
    self.connection.login(self.username, self.password)
  File "C:\Users\Arthur\AppData\Local\Programs\Python\Python39\lib\smtplib.py", line 745, in login
    raise last_exception
  File "C:\Users\Arthur\AppData\Local\Programs\Python\Python39\lib\smtplib.py", line 734, in login
    (code, resp) = self.auth(
  File "C:\Users\Arthur\AppData\Local\Programs\Python\Python39\lib\smtplib.py", line 657, in auth
    raise SMTPAuthenticationError(code, resp)
smtplib.SMTPAuthenticationError: (535, b'5.7.1 Authentication failed')
"POST /test_email_sending/4f555b1bb8bc729a665b8892df73119e2ef2eb50dffaf0d5c546cf23 HTTP/1.1" 500 98644
Internal Server Error: /send_bulletins/4f555b1bb8bc729a665b8892df73119e2ef2eb50dffaf0d5c546cf23
Traceback (most recent call last):
  File "C:\Users\Arthur\AppData\Local\Programs\Python\Python39\lib\site-packages\django\core\handlers\exception.py", line 47, in inner
    response = get_response(request)
  File "C:\Users\Arthur\AppData\Local\Programs\Python\Python39\lib\site-packages\django\core\handlers\base.py", line 181, in _get_response
    response = wrapped_callback(request, *callback_args, **callback_kwargs)
  File "C:\Users\Arthur\coopvote\app\newref\views.py", line 299, in send_bulletins
    mail_bulletin(rawvote)
  File "C:\Users\Arthur\coopvote\app\newref\views.py", line 279, in mail_bulletin
    msg = EmailMultiAlternatives(
TypeError: __init__() got an unexpected keyword argument 'text_content'
"GET /send_bulletins/4f555b1bb8bc729a665b8892df73119e2ef2eb50dffaf0d5c546cf23 HTTP/1.1" 500 85450
Internal Server Error: /send_bulletins/35f757ad7f998eb6dd3dd1cd3b5c6de97348b84a951f13de25355177
Traceback (most recent call last):
  File "C:\Users\Arthur\AppData\Local\Programs\Python\Python39\lib\site-packages\django\core\handlers\exception.py", line 47, in inner
    response = get_response(request)
  File "C:\Users\Arthur\AppData\Local\Programs\Python\Python39\lib\site-packages\django\core\handlers\base.py", line 181, in _get_response
    response = wrapped_callback(request, *callback_args, **callback_kwargs)
  File "C:\Users\Arthur\coopvote\app\newref\views.py", line 299, in send_bulletins
    mail_bulletin(rawvote)
  File "C:\Users\Arthur\coopvote\app\newref\views.py", line 279, in mail_bulletin
    msg = EmailMultiAlternatives(
TypeError: __init__() got an unexpected keyword argument 'bodypy'
"GET /send_bulletins/35f757ad7f998eb6dd3dd1cd3b5c6de97348b84a951f13de25355177 HTTP/1.1" 500 85634
Internal Server Error: /preview_bulletin/d2d5c076b2435565f66649edd604dd5987163e8a8240953144ec652f
Traceback (most recent call last):
  File "C:\Users\Arthur\AppData\Local\Programs\Python\Python39\lib\site-packages\django\core\handlers\exception.py", line 47, in inner
    response = get_response(request)
  File "C:\Users\Arthur\AppData\Local\Programs\Python\Python39\lib\site-packages\django\core\handlers\base.py", line 181, in _get_response
    response = wrapped_callback(request, *callback_args, **callback_kwargs)
  File "C:\Users\Arthur\coopvote\app\newref\views.py", line 264, in preview_bulletin
    html = generate_html_bulletin(rawvote)
  File "C:\Users\Arthur\coopvote\app\newref\views.py", line 208, in generate_html_bulletin
    abs_path = "http://"+settings.DOMAIN_NAME
  File "C:\Users\Arthur\AppData\Local\Programs\Python\Python39\lib\site-packages\django\conf\__init__.py", line 83, in __getattr__
    val = getattr(self._wrapped, name)
AttributeError: 'Settings' object has no attribute 'DOMAIN_NAME'
"GET /preview_bulletin/d2d5c076b2435565f66649edd604dd5987163e8a8240953144ec652f HTTP/1.1" 500 77153
